Workbook

Sheet ML
B1: HC2 | C1: CMFM | D1: RT | E1: BORF | F1: CIF | H1: HC2 | I1: CMFM | J1: RT | K1: BORF | L1: CIF | N1: HC2 | O1: CIF
A2: ArticularyWordRecognition | B2: =ROUND(N2,3) -> 0.993 | C2: =VLOOKUP(A2,ML!D34:E342,2,FALSE) -> 0.988 | D2: =ROUND(VLOOKUP(A2,ML!$G$34:$H$342,2,FALSE),3) -> 0.993 | E2: =VLOOKUP(A2,ML!$J$34:$K$342,2,FALSE) -> 0.993 | F2: =ROUND(O2,3) -> 0.983 | H2: =_xlfn.RANK.AVG(B2,$B2:$F2) -> 2 | I2: =_xlfn.RANK.AVG(C2,$B2:$F2) -> 4 | J2: =_xlfn.RANK.AVG(D2,$B2:$F2) -> 2 | K2: =_xlfn.RANK.AVG(E2,$B2:$F2) -> 2 | L2: =_xlfn.RANK.AVG(F2,$B2:$F2) -> 5 | N2: 0.99333333 | O2: 0.98333333
A3: AtrialFibrillation | B3: =ROUND(N3,3) -> 0.267 | C3: =VLOOKUP(A3,ML!D35:E64,2,FALSE) -> 0.191 | D3: =VLOOKUP(A3,ML!$G$34:$H$342,2,FALSE) -> 0.2 | E3: =VLOOKUP(A3,ML!$J$34:$K$342,2,FALSE) -> 0.267 | F3: =ROUND(O3,3) -> 0.333 | H3: =_xlfn.RANK.AVG(B3,$B3:$F3) -> 2.5 | I3: =_xlfn.RANK.AVG(C3,$B3:$F3) -> 5 | J3: =_xlfn.RANK.AVG(D3,$B3:$F3) -> 4 | K3: =_xlfn.RANK.AVG(E3,$B3:$F3) -> 2.5 | L3: =_xlfn.RANK.AVG(F3,$B3:$F3) -> 1 | N3: 0.26666667 | O3: 0.33333333
A4: BasicMotions | B4: =ROUND(N4,3) -> 1 | C4: =VLOOKUP(A4,ML!D36:E65,2,FALSE) -> 0.982 | D4: =VLOOKUP(A4,ML!$G$34:$H$342,2,FALSE) -> 1 | E4: =VLOOKUP(A4,ML!$J$34:$K$342,2,FALSE) -> 0.975 | F4: =ROUND(O4,3) -> 1 | H4: =_xlfn.RANK.AVG(B4,$B4:$F4) -> 2 | I4: =_xlfn.RANK.AVG(C4,$B4:$F4) -> 4 | J4: =_xlfn.RANK.AVG(D4,$B4:$F4) -> 2 | K4: =_xlfn.RANK.AVG(E4,$B4:$F4) -> 5 | L4: =_xlfn.RANK.AVG(F4,$B4:$F4) -> 2 | N4: 1 | O4: 1
A5: Cricket | B5: =ROUND(N5,3) -> 1 | C5: =VLOOKUP(A5,ML!D37:E66,2,FALSE) -> 0.977 | D5: =VLOOKUP(A5,ML!$G$34:$H$342,2,FALSE) -> 1 | E5: =VLOOKUP(A5,ML!$J$34:$K$342,2,FALSE) -> 1 | F5: =ROUND(O5,3) -> 0.986 | H5: =_xlfn.RANK.AVG(B5,$B5:$F5) -> 2 | I5: =_xlfn.RANK.AVG(C5,$B5:$F5) -> 5 | J5: =_xlfn.RANK.AVG(D5,$B5:$F5) -> 2 | K5: =_xlfn.RANK.AVG(E5,$B5:$F5) -> 2 | L5: =_xlfn.RANK.AVG(F5,$B5:$F5) -> 4 | N5: 1 | O5: 0.98611111
A6: DuckDuckGeese | B6: =ROUND(N6,3) -> 0.56 | C6: =VLOOKUP(A6,ML!D38:E67,2,FALSE) -> 0.51 | D6: =VLOOKUP(A6,ML!$G$34:$H$342,2,FALSE) -> 0.18 | E6: =VLOOKUP(A6,ML!$J$34:$K$342,2,FALSE) -> 0.44 | F6: =ROUND(O6,3) -> 0.44 | H6: =_xlfn.RANK.AVG(B6,$B6:$F6) -> 1 | I6: =_xlfn.RANK.AVG(C6,$B6:$F6) -> 2 | J6: =_xlfn.RANK.AVG(D6,$B6:$F6) -> 5 | K6: =_xlfn.RANK.AVG(E6,$B6:$F6) -> 3.5 | L6: =_xlfn.RANK.AVG(F6,$B6:$F6) -> 3.5 | N6: 0.56 | O6: 0.44
A7: ERing | B7: =ROUND(N7,3) -> 0.989 | C7: =VLOOKUP(A7,ML!D39:E68,2,FALSE) -> 0.931 | D7: =VLOOKUP(A7,ML!$G$34:$H$342,2,FALSE) -> 0.8185 | E7: =VLOOKUP(A7,ML!$J$34:$K$342,2,FALSE) -> 0.952 | F7: =ROUND(O7,3) -> 0.981 | H7: =_xlfn.RANK.AVG(B7,$B7:$F7) -> 1 | I7: =_xlfn.RANK.AVG(C7,$B7:$F7) -> 4 | J7: =_xlfn.RANK.AVG(D7,$B7:$F7) -> 5 | K7: =_xlfn.RANK.AVG(E7,$B7:$F7) -> 3 | L7: =_xlfn.RANK.AVG(F7,$B7:$F7) -> 2 | N7: 0.98888889 | O7: 0.98148148
A8: EigenWorms | B8: =ROUND(N8,3) -> 0.947 | C8: =VLOOKUP(A8,ML!D40:E69,2,FALSE) -> 0.895 | D8: =VLOOKUP(A8,ML!$G$34:$H$342,2,FALSE) -> 0.5878 | E8: =VLOOKUP(A8,ML!$J$34:$K$342,2,FALSE) -> 0.87 | F8: =ROUND(O8,3) -> 0.916 | H8: =_xlfn.RANK.AVG(B8,$B8:$F8) -> 1 | I8: =_xlfn.RANK.AVG(C8,$B8:$F8) -> 3 | J8: =_xlfn.RANK.AVG(D8,$B8:$F8) -> 5 | K8: =_xlfn.RANK.AVG(E8,$B8:$F8) -> 4 | L8: =_xlfn.RANK.AVG(F8,$B8:$F8) -> 2 | N8: 0.94656489 | O8: 0.91603053
A9: Epilepsy | B9: =ROUND(N9,3) -> 1 | C9: =VLOOKUP(A9,ML!D41:E70,2,FALSE) -> 0.999 | D9: =VLOOKUP(A9,ML!$G$34:$H$342,2,FALSE) -> 0.9928 | E9: =VLOOKUP(A9,ML!$J$34:$K$342,2,FALSE) -> 0.993 | F9: =ROUND(O9,3) -> 0.986 | H9: =_xlfn.RANK.AVG(B9,$B9:$F9) -> 1 | I9: =_xlfn.RANK.AVG(C9,$B9:$F9) -> 2 | J9: =_xlfn.RANK.AVG(D9,$B9:$F9) -> 4 | K9: =_xlfn.RANK.AVG(E9,$B9:$F9) -> 3 | L9: =_xlfn.RANK.AVG(F9,$B9:$F9) -> 5 | N9: 1 | O9: 0.98550725
A10: EthanolConcentration | B10: =ROUND(N10,3) -> 0.772 | C10: =VLOOKUP(A10,ML!D42:E71,2,FALSE) -> 0.26 | D10: =VLOOKUP(A10,ML!$G$34:$H$342,2,FALSE) -> 0.3954 | E10: =VLOOKUP(A10,ML!$J$34:$K$342,2,FALSE) -> 0.369 | F10: =ROUND(O10,3) -> 0.734 | H10: =_xlfn.RANK.AVG(B10,$B10:$F10) -> 1 | I10: =_xlfn.RANK.AVG(C10,$B10:$F10) -> 5 | J10: =_xlfn.RANK.AVG(D10,$B10:$F10) -> 3 | K10: =_xlfn.RANK.AVG(E10,$B10:$F10) -> 4 | L10: =_xlfn.RANK.AVG(F10,$B10:$F10) -> 2 | N10: 0.77186312 | O10: 0.7338403
A11: FaceDetection | B11: =ROUND(N11,3) -> 0.66 | C11: =VLOOKUP(A11,ML!D43:E72,2,FALSE) -> 0.557 | D11: =VLOOKUP(A11,ML!$G$34:$H$342,2,FALSE) -> 0.5074 | E11: =VLOOKUP(A11,ML!$J$34:$K$342,2,FALSE) -> 0.589 | F11: =ROUND(O11,3) -> 0.627 | H11: =_xlfn.RANK.AVG(B11,$B11:$F11) -> 1 | I11: =_xlfn.RANK.AVG(C11,$B11:$F11) -> 4 | J11: =_xlfn.RANK.AVG(D11,$B11:$F11) -> 5 | K11: =_xlfn.RANK.AVG(E11,$B11:$F11) -> 3 | L11: =_xlfn.RANK.AVG(F11,$B11:$F11) -> 2 | N11: 0.66032917 | O11: 0.62712826
A12: FingerMovements | B12: =ROUND(N12,3) -> 0.53 | C12: =VLOOKUP(A12,ML!D44:E73,2,FALSE) -> 0.501 | D12: =VLOOKUP(A12,ML!$G$34:$H$342,2,FALSE) -> 0.59 | E12: =VLOOKUP(A12,ML!$J$34:$K$342,2,FALSE) -> 0.56 | F12: =ROUND(O12,3) -> 0.52 | H12: =_xlfn.RANK.AVG(B12,$B12:$F12) -> 3 | I12: =_xlfn.RANK.AVG(C12,$B12:$F12) -> 5 | J12: =_xlfn.RANK.AVG(D12,$B12:$F12) -> 1 | K12: =_xlfn.RANK.AVG(E12,$B12:$F12) -> 2 | L12: =_xlfn.RANK.AVG(F12,$B12:$F12) -> 4 | N12: 0.53 | O12: 0.52
A13: HandMovementDirection | B13: =ROUND(N13,3) -> 0.473 | C13: =VLOOKUP(A13,ML!D45:E74,2,FALSE) -> 0.245 | D13: =VLOOKUP(A13,ML!$G$34:$H$342,2,FALSE) -> 0.3378 | E13: =VLOOKUP(A13,ML!$J$34:$K$342,2,FALSE) -> 0.284 | F13: =ROUND(O13,3) -> 0.595 | H13: =_xlfn.RANK.AVG(B13,$B13:$F13) -> 2 | I13: =_xlfn.RANK.AVG(C13,$B13:$F13) -> 5 | J13: =_xlfn.RANK.AVG(D13,$B13:$F13) -> 3 | K13: =_xlfn.RANK.AVG(E13,$B13:$F13) -> 4 | L13: =_xlfn.RANK.AVG(F13,$B13:$F13) -> 1 | N13: 0.47297297 | O13: 0.59459459
A14: Handwriting | B14: =ROUND(N14,3) -> 0.548 | C14: =VLOOKUP(A14,ML!D46:E75,2,FALSE) -> 0.274 | D14: =VLOOKUP(A14,ML!$G$34:$H$342,2,FALSE) -> 0.2694 | E14: =VLOOKUP(A14,ML!$J$34:$K$342,2,FALSE) -> 0.52 | F14: =ROUND(O14,3) -> 0.356 | H14: =_xlfn.RANK.AVG(B14,$B14:$F14) -> 1 | I14: =_xlfn.RANK.AVG(C14,$B14:$F14) -> 4 | J14: =_xlfn.RANK.AVG(D14,$B14:$F14) -> 5 | K14: =_xlfn.RANK.AVG(E14,$B14:$F14) -> 2 | L14: =_xlfn.RANK.AVG(F14,$B14:$F14) -> 3 | N14: 0.54823529 | O14: 0.35647059
... A27: UWaveGestureLibrary | B27: =ROUND(N27,3) -> 0.928 | C27: =VLOOKUP(A27,ML!D59:E88,2,FALSE) -> 0.775 | D27: =VLOOKUP(A27,ML!$G$34:$H$342,2,FALSE) -> 0.875 | E27: =VLOOKUP(A27,ML!$J$34:$K$342,2,FALSE) -> 0.944 | F27: =ROUND(O27,3) -> 0.925 | H27: =_xlfn.RANK.AVG(B27,$B27:$F27) -> 2 | I27: =_xlfn.RANK.AVG(C27,$B27:$F27) -> 5 | J27: =_xlfn.RANK.AVG(D27,$B27:$F27) -> 4 | K27: =_xlfn.RANK.AVG(E27,$B27:$F27) -> 1 | L27: =_xlfn.RANK.AVG(F27,$B27:$F27) -> 3 | N27: 0.928125 | O27: 0.925
A29: Average accuracy | B29: =AVERAGE(N2:N27) -> 0.74785266 | C29: =AVERAGE(C2:C27) -> 0.66742308 | D29: =AVERAGE(D2:D27) -> 0.60732308 | E29: =AVERAGE(E2:E27) -> 0.68992308 | F29: =AVERAGE(O2:O27) -> 0.72604091 | H29: =AVERAGE(H2:H27) -> 1.5769231 | I29: =AVERAGE(I2:I27) -> 3.7692308 | J29: =AVERAGE(J2:J27) -> 3.75 | K29: =AVERAGE(K2:K27) -> 3.2115385 | L29: =AVERAGE(L2:L27) -> 2.6923077
A33: HC2 | B33: Middlehurst21hc2 | D33: Baldan2021CMFMTS | E33: CMFM_RF | G33: Bahri2022RT | H33: RT_100 | J33: BORF | K33: Spinnato2024BORF | M33: Resamples: | N33: DTW-D
A34: ArticularyWordRecognition | B34: 0.99333333 | D34: ArticularyWordRecognition | E34: 0.988 | G34: ArticularyWordRecognition | H34: 0.9933 | J34: ACSF1 | K34: 0.61 | M34: ArticularyWordRecognition | N34: 0.98666667
A35: AtrialFibrillation | B35: 0.26666667 | D35: AtrialFibrillation | E35: 0.191 | G35: AtrialFibrillation | H35: 0.2 | J35: Adiac | K35: 0.652 | M35: AtrialFibrillation | N35: 0.2
A36: BasicMotions | B36: 1 | D36: BasicMotions | E36: 0.982 | G36: BasicMotions | H36: 1 | J36: AGW-X | K36: 0.656 | M36: BasicMotions | N36: 0.975
A37: Cricket | B37: 1 | D37: CharacterTrajectories | E37: 0.97 | G37: Cricket | H37: 1 | J37: AGW-Y | K37: 0.706 | M37: Cricket | N37: 1
A38: DuckDuckGeese | B38: 0.56 | D38: Cricket | E38: 0.977 | G38: DuckDuckGeese | H38: 0.18 | J38: AGW-Z | K38: 0.633 | M38: DuckDuckGeese | N38: 0.58
A39: ERing | B39: 0.98888889 | D39: DuckDuckGeese | E39: 0.51 | G39: EigenWorms | H39: 0.5878 | J39: ArrowHead | K39: 0.829 | M39: ERing | N39: 0.91481481
A40: EigenWorms | B40: 0.94656489 | D40: EigenWorms | E40: 0.895 | G40: Epilepsy | H40: 0.9928 | J40: ArticularyWordRecognition | K40: 0.993 | M40: EigenWorms | N40: 0.61832061
A41: Epilepsy | B41: 1 | D41: Epilepsy | E41: 0.999 | G41: EthanolConcentration | H41: 0.3954 | J41: AtrialFibrillation | K41: 0.267 | M41: Epilepsy | N41: 0.96376812
A42: EthanolConcentration | B42: 0.77186312 | D42: ERing | E42: 0.931 | G42: ERing | H42: 0.8185 | J42: BME | K42: 0.98 | M42: EthanolConcentration | N42: 0.32319392
A43: FaceDetection | B43: 0.66032917 | D43: EthanolConcentration | E43: 0.26 | G43: FaceDetection | H43: 0.5074 | J43: BasicMotions | K43: 0.975 | M43: FaceDetection | N43: 0.52866061
A44: FingerMovements | B44: 0.53 | D44: FaceDetection | E44: 0.557 | G44: FingerMovements | H44: 0.59 | J44: Beef | K44: 0.733 | M44: FingerMovements | N44: 0.53
A45: HandMovementDirection | B45: 0.47297297 | D45: FingerMovements | E45: 0.501 | G45: HandMovementDirection | H45: 0.3378 | J45: BeetleFly | K45: 0.9 | M45: HandMovementDirection | N45: 0.18918919
... A59: UWaveGestureLibrary | B59: 0.928125 | D59: SelfRegulationSCP1 | E59: 0.82 | G59: UWaveGestureLibrary | H59: 0.875 | J59: Crop | K59: 0.678 | M59: UWaveGestureLibrary | N59: 0.903125
D60: SelfRegulationSCP2 | E60: 0.418 | J60: DiatomSR | K60: 0.98
B61: =AVERAGE(B34:B59) -> 0.74785266 | D61: SpokenArabicDigits | E61: 0.976 | J61: DP-OAG | K61: 0.77 | N61: =AVERAGE(N34:N59) -> 0.65381178
D62: StandWalkJump | E62: 0.363 | J62: DP-OC | K62: 0.743
D63: UWaveGestureLibrary | E63: 0.775 | J63: DP-TW | K63: 0.712
J64: DodgerLoopDay | K64: 0.537
J65: DodgerLoopGame | K65: 0.855
J66: DLWeekend | K66: 0.978
J67: DuckDuckGeese | K67: 0.44
J68: ECG200 | K68: 0.9
J69: ECGS5000 | K69: 0.944
...

Sheet Conv
B1: Disjoint-CNN | C1: XCM | D1: LITEMVTime
A2: ArticularyWordRecognition | B2: =ROUND(VLOOKUP($A2,$A$34:$G$64,2,FALSE)/100,3) -> 0.984 | C2: =ROUND(VLOOKUP($A2,$A$34:$G$64,3,FALSE)/100,3) -> 0.983 | D2: =ROUND(VLOOKUP($A2,$A$34:$G$64,7,FALSE)/100,3) -> 0.973
A3: AtrialFibrillation | B3: =ROUND(VLOOKUP($A3,$A$34:$G$64,2,FALSE)/100,3) -> 0.375 | C3: =ROUND(VLOOKUP($A3,$A$34:$G$64,3,FALSE)/100,3) -> 0.467 | D3: =ROUND(VLOOKUP($A3,$A$34:$G$64,7,FALSE)/100,3) -> 0.133
A4: BasicMotions | B4: =ROUND(VLOOKUP($A4,$A$34:$G$64,2,FALSE)/100,3) -> 1 | C4: =ROUND(VLOOKUP($A4,$A$34:$G$64,3,FALSE)/100,3) -> 1 | D4: =ROUND(VLOOKUP($A4,$A$34:$G$64,7,FALSE)/100,3) -> 1
A5: Cricket | B5: =ROUND(VLOOKUP($A5,$A$34:$G$64,2,FALSE)/100,3) -> 0.999 | C5: =ROUND(VLOOKUP($A5,$A$34:$G$64,3,FALSE)/100,3) -> 1 | D5: =ROUND(VLOOKUP($A5,$A$34:$G$64,7,FALSE)/100,3) -> 0.986
A6: DuckDuckGeese | B6: =ROUND(VLOOKUP($A6,$A$34:$G$64,2,FALSE)/100,3) -> 0.644 | C6: =ROUND(VLOOKUP($A6,$A$34:$G$64,3,FALSE)/100,3) -> 0.7 | D6: =ROUND(VLOOKUP($A6,$A$34:$G$64,7,FALSE)/100,3) -> 0.18
A7: ERing | B7: =ROUND(VLOOKUP($A7,$A$34:$G$64,2,FALSE)/100,3) -> 0.964 | C7: =ROUND(VLOOKUP($A7,$A$34:$G$64,3,FALSE)/100,3) -> 0.133 | D7: =ROUND(VLOOKUP($A7,$A$34:$G$64,7,FALSE)/100,3) -> 0.844
A8: EigenWorms | B8: =ROUND(VLOOKUP($A8,$A$34:$G$64,2,FALSE)/100,3) -> 0.593 | C8: =ROUND(VLOOKUP($A8,$A$34:$G$64,3,FALSE)/100,3) -> 0.435 | D8: =ROUND(VLOOKUP($A8,$A$34:$G$64,7,FALSE)/100,3) -> 0.939
A9: Epilepsy | B9: =ROUND(VLOOKUP($A9,$A$34:$G$64,2,FALSE)/100,3) -> 0.989 | C9: =ROUND(VLOOKUP($A9,$A$34:$G$64,3,FALSE)/100,3) -> 0.993 | D9: =ROUND(VLOOKUP($A9,$A$34:$G$64,7,FALSE)/100,3) -> 0.993
A10: EthanolConcentration | B10: =ROUND(VLOOKUP($A10,$A$34:$G$64,2,FALSE)/100,3) -> 0.309 | C10: =ROUND(VLOOKUP($A10,$A$34:$G$64,3,FALSE)/100,3) -> 0.346 | D10: =ROUND(VLOOKUP($A10,$A$34:$G$64,7,FALSE)/100,3) -> 0.692
A11: FaceDetection | B11: =ROUND(VLOOKUP($A11,$A$34:$G$64,2,FALSE)/100,3) -> 0.567 | C11: =ROUND(VLOOKUP($A11,$A$34:$G$64,3,FALSE)/100,3) -> 0.639 | D11: =ROUND(VLOOKUP($A11,$A$34:$G$64,7,FALSE)/100,3) -> 0.61
A12: FingerMovements | B12: =ROUND(VLOOKUP($A12,$A$34:$G$64,2,FALSE)/100,3) -> 0.604 | C12: =ROUND(VLOOKUP($A12,$A$34:$G$64,3,FALSE)/100,3) -> 0.6 | D12: =ROUND(VLOOKUP($A12,$A$34:$G$64,7,FALSE)/100,3) -> 0.56
A13: HandMovementDirection | B13: =ROUND(VLOOKUP($A13,$A$34:$G$64,2,FALSE)/100,3) -> 0.324 | C13: =ROUND(VLOOKUP($A13,$A$34:$G$64,3,FALSE)/100,3) -> 0.446 | D13: =ROUND(VLOOKUP($A13,$A$34:$G$64,7,FALSE)/100,3) -> 0.351
... A27: UWaveGestureLibrary | B27: =ROUND(VLOOKUP($A27,$A$34:$G$64,2,FALSE)/100,3) -> 0.924 | C27: =ROUND(VLOOKUP($A27,$A$34:$G$64,3,FALSE)/100,3) -> 0.894 | D27: =ROUND(VLOOKUP($A27,$A$34:$G$64,7,FALSE)/100,3) -> 0.847
B29: =AVERAGE(B2:B27) -> 0.69892308 | C29: =AVERAGE(C2:C27) -> 0.67261538 | D29: =AVERAGE(D2:D27) -> 0.68207692
A33: Dataset | B33: Disjoint-CNN | C33: XCM | D33: TPS (IT+TPS+PE) | E33: FreConvNet | F33: HDTCNet | G33: LITEMVTime
A34: ArticularyWordRecognition | B34: 98.44 | C34: 98.3 | D34: 99 | E34: 99.3 | F34: 99.3 | G34: 97.33
A35: AtrialFibrillation | B35: 37.48 | C35: 46.7 | D35: 46.7 | E35: 53.3 | F35: 46.7 | G35: 13.33
A36: BasicMotions | B36: 100 | C36: 100 | D36: 100 | E36: 100 | F36: 100 | G36: 100
A37: CharacterTrajectories | C37: 99.5 | D37: 99.9 | G37: 99.58
A38: Cricket | B38: 99.91 | C38: 100 | D38: 100 | E38: 100 | F38: 100 | G38: 98.61
A39: DuckDuckGeese | B39: 64.4 | C39: 70 | D39: 74 | G39: 18
A40: EigenWorms | B40: 59.34 | C40: 43.5 | D40: 95.4 | G40: 93.89
A41: Epilepsy | B41: 98.87 | C41: 99.3 | D41: 97.8 | E41: 99.1 | F41: 100 | G41: 99.28
A42: ERing | B42: 96.39 | C42: 13.3 | D42: 94.8 | F42: 92.6 | G42: 84.44
A43: EthanolConcentration | B43: 30.93 | C43: 34.6 | D43: 36.1 | E43: 36 | F43: 32.6 | G43: 69.2
A44: FaceDetection | B44: 56.67 | C44: 63.9 | D44: 64.8 | E44: 65.1 | F44: 66.7 | G44: 61.01
A45: FingerMovements | B45: 60.37 | C45: 60 | D45: 63 | E45: 63.8 | F45: 67 | G45: 56
A46: HandMovementDirection | B46: 32.44 | C46: 44.6 | D46: 44.6 | E46: 54.1 | F46: 48.6 | G46: 35.14
A47: Handwriting | B47: 32.09 | C47: 41.2 | D47: 58.7 | E47: 57.5 | F47: 68.3 | G47: 40
A48: Heartbeat | B48: 75.94 | C48: 77.6 | D48: 78 | E48: 77.6 | F48: 80.3 | G48: 61.46
A49: InsectWingbeat | C49: 10.5 | D49: 69.5 | E49: 76.6 | G49: 61.72
A50: JapaneseVowels | C50: 98.6 | D50: 99.2 | E50: 98.6 | F50: 99.2 | G50: 96.49
A51: Libras | B51: 91.62 | C51: 84.4 | D51: 90 | E51: 95.9 | F51: 96.1 | G51: 89.44
A52: LSST | B52: 54.7 | C52: 61.2 | D52: 65.2 | E52: 69.9 | F52: 43.8 | G52: 66.42
A53: MotorImagery | B53: 56.94 | C53: 54 | D53: 65 | E53: 64.3 | G53: 53
A54: NATOPS | B54: 96.67 | C54: 97.8 | D54: 95.6 | E54: 98.4 | F54: 98.9 | G54: 90
A55: PenDigits | B55: 99.47 | C55: 99.1 | D55: 99.1 | E55: 98.8 | F55: 99.3 | G55: 98.86
A56: PEMS-SF | B56: 81.74 | C56: 75.7 | D56: 81.5 | F56: 89.6 | G56: 79.19
A57: PhonemeSpectra | B57: 28.21 | C57: 22.5 | D57: 32.6 | E57: 26.1 | F57: 35.5 | G57: 15.81
...

Sheet Trans
B1: ConvTran | C1: PatchMTSC | L1: Dataset | M1: ConvTran | N1: PatchMTSC
A2: ArticularyWordRecognition | B2: =ROUND(VLOOKUP($A2,$L$2:$N$31,2,FALSE),3) -> 0.983 | C2: =ROUND(VLOOKUP($A2,$L$2:$N$31,3,FALSE),3) -> 0.993 | L2: ArticularyWordRecognition | M2: 0.9833 | N2: 0.993
A3: AtrialFibrillation | B3: =ROUND(VLOOKUP($A3,$L$2:$N$31,2,FALSE),3) -> 0.4 | C3: =ROUND(VLOOKUP($A3,$L$2:$N$31,3,FALSE),3) -> 0.533 | L3: AtrialFibrillation | M3: 0.4 | N3: 0.533
A4: BasicMotions | B4: =ROUND(VLOOKUP($A4,$L$2:$N$31,2,FALSE),3) -> 1 | C4: =ROUND(VLOOKUP($A4,$L$2:$N$31,3,FALSE),3) -> 1 | L4: BasicMotions | M4: 1 | N4: 1
A5: Cricket | B5: =ROUND(VLOOKUP($A5,$L$2:$N$31,2,FALSE),3) -> 1 | C5: =ROUND(VLOOKUP($A5,$L$2:$N$31,3,FALSE),3) -> 1 | L5: CharacterTrajectories | M5: 0.9922 | N5: 0.997
A6: DuckDuckGeese | B6: =ROUND(VLOOKUP($A6,$L$2:$N$31,2,FALSE),3) -> 0.62 | C6: =ROUND(VLOOKUP($A6,$L$2:$N$31,3,FALSE),3) -> 0.57 | L6: Cricket | M6: 1 | N6: 1
A7: ERing | B7: =ROUND(VLOOKUP($A7,$L$2:$N$31,2,FALSE),3) -> 0.963 | C7: =ROUND(VLOOKUP($A7,$L$2:$N$31,3,FALSE),3) -> 0.951 | L7: DuckDuckGeese | M7: 0.62 | N7: 0.57
A8: EigenWorms | B8: =ROUND(VLOOKUP($A8,$L$2:$N$31,2,FALSE),3) -> 0.593 | C8: =ROUND(VLOOKUP($A8,$L$2:$N$31,3,FALSE),3) -> 0.557 | L8: EigenWorms | M8: 0.5934 | N8: 0.557
A9: Epilepsy | B9: =ROUND(VLOOKUP($A9,$L$2:$N$31,2,FALSE),3) -> 0.986 | C9: =ROUND(VLOOKUP($A9,$L$2:$N$31,3,FALSE),3) -> 0.985 | L9: Epilepsy | M9: 0.9855 | N9: 0.985
A10: EthanolConcentration | B10: =ROUND(VLOOKUP($A10,$L$2:$N$31,2,FALSE),3) -> 0.361 | C10: =ROUND(VLOOKUP($A10,$L$2:$N$31,3,FALSE),3) -> 0.623 | L10: ERing | M10: 0.9629 | N10: 0.951
A11: FaceDetection | B11: =ROUND(VLOOKUP($A11,$L$2:$N$31,2,FALSE),3) -> 0.672 | C11: =ROUND(VLOOKUP($A11,$L$2:$N$31,3,FALSE),3) -> 0.68 | L11: EthanolConcentration | M11: 0.3612 | N11: 0.623
A12: FingerMovements | B12: =ROUND(VLOOKUP($A12,$L$2:$N$31,2,FALSE),3) -> 0.56 | C12: =ROUND(VLOOKUP($A12,$L$2:$N$31,3,FALSE),3) -> 0.614 | L12: FaceDetection | M12: 0.6722 | N12: 0.68
A13: HandMovementDirection | B13: =ROUND(VLOOKUP($A13,$L$2:$N$31,2,FALSE),3) -> 0.405 | C13: =ROUND(VLOOKUP($A13,$L$2:$N$31,3,FALSE),3) -> 0.662 | L13: FingerMovements | M13: 0.56 | N13: 0.614
... A27: UWaveGestureLibrary | B27: =ROUND(VLOOKUP($A27,$L$2:$N$31,2,FALSE),3) -> 0.891 | C27: =ROUND(VLOOKUP($A27,$L$2:$N$31,3,FALSE),3) -> 0.903 | L27: SelfRegulationSCP1 | M27: 0.918 | N27: 0.904
L28: SelfRegulationSCP2 | M28: 0.5833 | N28: 0.611
A29: Average accuracy | B29: =AVERAGE(B2:B27) -> 0.70996154 | C29: =AVERAGE(C2:C27) -> 0.7485 | L29: SpokenArabicDigits | M29: 0.9945 | N29: 0.995
L30: StandWalkJump | M30: 0.3333 | N30: 0.6
L31: UWaveGestureLibrary | M31: 0.8906 | N31: 0.903

Sheet Found
B1: TimesURL | C1: TS2Vec | N1: Dataset | O1: TimesURL | P1: TS2Vec
A2: ArticularyWordRecognition | B2: =ROUND(VLOOKUP($A2,$N$2:$P$33,2,FALSE),3) -> 0.99 | C2: =VLOOKUP($A2,$N$2:$P$33,3,FALSE) -> 0.987 | N2: ArticularyWordRecognition | O2: 0.99 | P2: 0.987
A3: AtrialFibrillation | B3: =ROUND(VLOOKUP($A3,$N$2:$P$33,2,FALSE),3) -> 0.4 | C3: =VLOOKUP($A3,$N$2:$P$33,3,FALSE) -> 0.2 | N3: AtrialFibrillation | O3: 0.4 | P3: 0.2
A4: BasicMotions | B4: =ROUND(VLOOKUP($A4,$N$2:$P$33,2,FALSE),3) -> 1 | C4: =VLOOKUP($A4,$N$2:$P$33,3,FALSE) -> 0.975 | N4: BasicMotions | O4: 1 | P4: 0.975
A5: Cricket | B5: =ROUND(VLOOKUP($A5,$N$2:$P$33,2,FALSE),3) -> 1 | C5: =VLOOKUP($A5,$N$2:$P$33,3,FALSE) -> 0.972 | N5: CharacterTrajectories | O5: 0.99 | P5: 0.995
A6: DuckDuckGeese | B6: =ROUND(VLOOKUP($A6,$N$2:$P$33,2,FALSE),3) -> 0.72 | C6: =VLOOKUP($A6,$N$2:$P$33,3,FALSE) -> 0.68 | N6: Cricket | O6: 1 | P6: 0.972
A7: ERing | B7: =ROUND(VLOOKUP($A7,$N$2:$P$33,2,FALSE),3) -> 0.985 | C7: =VLOOKUP($A7,$N$2:$P$33,3,FALSE) -> 0.874 | N7: DuckDuckGeese | O7: 0.72 | P7: 0.68
A8: EigenWorms | B8: =ROUND(VLOOKUP($A8,$N$2:$P$33,2,FALSE),3) -> 0.87 | C8: =VLOOKUP($A8,$N$2:$P$33,3,FALSE) -> 0.847 | N8: EigenWorms | O8: 0.87 | P8: 0.847
A9: Epilepsy | B9: =ROUND(VLOOKUP($A9,$N$2:$P$33,2,FALSE),3) -> 0.978 | C9: =VLOOKUP($A9,$N$2:$P$33,3,FALSE) -> 0.964 | N9: Epilepsy | O9: 0.978 | P9: 0.964
A10: EthanolConcentration | B10: =ROUND(VLOOKUP($A10,$N$2:$P$33,2,FALSE),3) -> 0.304 | C10: =VLOOKUP($A10,$N$2:$P$33,3,FALSE) -> 0.308 | N10: ERing | O10: 0.985 | P10: 0.874
A11: FaceDetection | B11: =ROUND(VLOOKUP($A11,$N$2:$P$33,2,FALSE),3) -> 0.608 | C11: =VLOOKUP($A11,$N$2:$P$33,3,FALSE) -> 0.501 | N11: EthanolConcentration | O11: 0.304 | P11: 0.308
A12: FingerMovements | B12: =ROUND(VLOOKUP($A12,$N$2:$P$33,2,FALSE),3) -> 0.66 | C12: =VLOOKUP($A12,$N$2:$P$33,3,FALSE) -> 0.48 | N12: FaceDetection | O12: 0.608 | P12: 0.501
A13: HandMovementDirection | B13: =ROUND(VLOOKUP($A13,$N$2:$P$33,2,FALSE),3) -> 0.432 | C13: =VLOOKUP($A13,$N$2:$P$33,3,FALSE) -> 0.338 | N13: FingerMovements | O13: 0.66 | P13: 0.48
... A27: UWaveGestureLibrary | B27: =ROUND(VLOOKUP($A27,$N$2:$P$33,2,FALSE),3) -> 0.919 | C27: =VLOOKUP($A27,$N$2:$P$33,3,FALSE) -> 0.906 | N27: SelfRegulationSCP2 | O27: 0.6 | P27: 0.578
N28: SpokenArabicDigits | O28: 0.985 | P28: 0.988
B29: =AVERAGE(B2:B27) -> 0.7355 | C29: =AVERAGE(C2:C27) -> 0.68030769 | N29: StandWalkJump | O29: 0.467 | P29: 0.467
N30: UWaveGestureLibrary | O30: 0.919 | P30: 0.906
N31: InsectWingbeat | O31: 0.473 | P31: 0.466
N32: Avg. ACC | O32: 0.752 | P32: 0.704
N33: Avg. Rank | O33: 1.367 | P33: 3.567

Sheet Other
B1: RankSCL | F1: Dataset | G1: RankSCL
A2: ArticularyWordRecognition | B2: =ROUND(VLOOKUP($A2,F2:G31,2,FALSE),3) -> 0.977 | F2: ArticularyWordRecognition | G2: 0.977
A3: AtrialFibrillation | B3: =ROUND(VLOOKUP($A3,F3:G32,2,FALSE),3) -> 0.293 | F3: AtrialFibrillation | G3: 0.293
A4: BasicMotions | B4: =ROUND(VLOOKUP($A4,F4:G33,2,FALSE),3) -> 1 | F4: BasicMotions | G4: 1
A5: Cricket | B5: =ROUND(VLOOKUP($A5,F5:G34,2,FALSE),3) -> 0.986 | F5: CharacterTrajectories | G5: 0.996
A6: DuckDuckGeese | B6: =ROUND(VLOOKUP($A6,F6:G35,2,FALSE),3) -> 0.604 | F6: Cricket | G6: 0.986
A7: ERing | B7: =ROUND(VLOOKUP($A7,F7:G36,2,FALSE),3) -> 0.913 | F7: DuckDuckGeese | G7: 0.604
A8: EigenWorms | B8: =ROUND(VLOOKUP($A8,F8:G37,2,FALSE),3) -> 0.727 | F8: EigenWorms | G8: 0.727
A9: Epilepsy | B9: =ROUND(VLOOKUP($A9,F9:G38,2,FALSE),3) -> 0.975 | F9: Epilepsy | G9: 0.975
A10: EthanolConcentration | B10: =ROUND(VLOOKUP($A10,F10:G39,2,FALSE),3) -> 0.304 | F10: ERing | G10: 0.913
A11: FaceDetection | B11: =ROUND(VLOOKUP($A11,F11:G40,2,FALSE),3) -> 0.637 | F11: EthanolConcentration | G11: 0.304
A12: FingerMovements | B12: =ROUND(VLOOKUP($A12,F12:G41,2,FALSE),3) -> 0.528 | F12: FaceDetection | G12: 0.637
A13: HandMovementDirection | B13: =ROUND(VLOOKUP($A13,F13:G42,2,FALSE),3) -> 0.322 | F13: FingerMovements | G13: 0.528
... A27: UWaveGestureLibrary | B27: =ROUND(VLOOKUP($A27,F27:G56,2,FALSE),3) -> 0.873 | F27: SelfRegulationSCP2 | G27: 0.549
F28: SpokenArabicDigits | G28: 0.989
A29: AverAGE | B29: =AVERAGE(B2:B27) -> 0.69088462 | F29: StandWalkJump | G29: 0.533
F30: UWaveGestureLibrary | G30: 0.873
F31: InsectWingbeat | G31: 0.518

Sheet Combined30

Sheet Combined26
B1: HC2 | C1: Disjoint-CNN | D1: XCM | E1: LITEMVTime | F1: ConvTran | G1: PatchMTSC | H1: TimesURL | I1: TS2Vec | J1: RankSCL | L1: =B1 -> HC2 | M1: =C1 -> Disjoint-CNN | N1: =D1 -> XCM | O1: =E1 -> LITEMVTime | P1: =F1 -> ConvTran | Q1: =G1 -> PatchMTSC | R1: =H1 -> TimesURL | S1: =I1 -> TS2Vec | T1: =J1 -> RankSCL
A2: ArticularyWordRecognition | B2: 0.993 | C2: 0.984 | D2: 0.983 | E2: 0.973 | F2: 0.983 | G2: 0.993 | H2: 0.99 | I2: 0.987 | J2: 0.977 | L2: =_xlfn.RANK.AVG(B2,$B2:$J2) -> 1.5 | M2: =_xlfn.RANK.AVG(C2,$B2:$J2) -> 5 | N2: =_xlfn.RANK.AVG(D2,$B2:$J2) -> 6.5 | O2: =_xlfn.RANK.AVG(E2,$B2:$J2) -> 9 | P2: =_xlfn.RANK.AVG(F2,$B2:$J2) -> 6.5 | Q2: =_xlfn.RANK.AVG(G2,$B2:$J2) -> 1.5 | R2: =_xlfn.RANK.AVG(H2,$B2:$J2) -> 3 | S2: =_xlfn.RANK.AVG(I2,$B2:$J2) -> 4 | T2: =_xlfn.RANK.AVG(J2,$B2:$J2) -> 8
A3: AtrialFibrillation | B3: 0.267 | C3: 0.375 | D3: 0.467 | E3: 0.133 | F3: 0.4 | G3: 0.533 | H3: 0.4 | I3: 0.2 | J3: 0.293 | L3: =_xlfn.RANK.AVG(B3,$B3:$J3) -> 7 | M3: =_xlfn.RANK.AVG(C3,$B3:$J3) -> 5 | N3: =_xlfn.RANK.AVG(D3,$B3:$J3) -> 2 | O3: =_xlfn.RANK.AVG(E3,$B3:$J3) -> 9 | P3: =_xlfn.RANK.AVG(F3,$B3:$J3) -> 3.5 | Q3: =_xlfn.RANK.AVG(G3,$B3:$J3) -> 1 | R3: =_xlfn.RANK.AVG(H3,$B3:$J3) -> 3.5 | S3: =_xlfn.RANK.AVG(I3,$B3:$J3) -> 8 | T3: =_xlfn.RANK.AVG(J3,$B3:$J3) -> 6
A4: BasicMotions | B4: 1 | C4: 1 | D4: 1 | E4: 1 | F4: 1 | G4: 1 | H4: 1 | I4: 0.975 | J4: 1 | L4: =_xlfn.RANK.AVG(B4,$B4:$J4) -> 4.5 | M4: =_xlfn.RANK.AVG(C4,$B4:$J4) -> 4.5 | N4: =_xlfn.RANK.AVG(D4,$B4:$J4) -> 4.5 | O4: =_xlfn.RANK.AVG(E4,$B4:$J4) -> 4.5 | P4: =_xlfn.RANK.AVG(F4,$B4:$J4) -> 4.5 | Q4: =_xlfn.RANK.AVG(G4,$B4:$J4) -> 4.5 | R4: =_xlfn.RANK.AVG(H4,$B4:$J4) -> 4.5 | S4: =_xlfn.RANK.AVG(I4,$B4:$J4) -> 9 | T4: =_xlfn.RANK.AVG(J4,$B4:$J4) -> 4.5
A5: Cricket | B5: 1 | C5: 0.999 | D5: 1 | E5: 0.986 | F5: 1 | G5: 1 | H5: 1 | I5: 0.972 | J5: 0.986 | L5: =_xlfn.RANK.AVG(B5,$B5:$J5) -> 3 | M5: =_xlfn.RANK.AVG(C5,$B5:$J5) -> 6 | N5: =_xlfn.RANK.AVG(D5,$B5:$J5) -> 3 | O5: =_xlfn.RANK.AVG(E5,$B5:$J5) -> 7.5 | P5: =_xlfn.RANK.AVG(F5,$B5:$J5) -> 3 | Q5: =_xlfn.RANK.AVG(G5,$B5:$J5) -> 3 | R5: =_xlfn.RANK.AVG(H5,$B5:$J5) -> 3 | S5: =_xlfn.RANK.AVG(I5,$B5:$J5) -> 9 | T5: =_xlfn.RANK.AVG(J5,$B5:$J5) -> 7.5
A6: DuckDuckGeese | B6: 0.56 | C6: 0.644 | D6: 0.7 | E6: 0.18 | F6: 0.62 | G6: 0.57 | H6: 0.72 | I6: 0.68 | J6: 0.604 | L6: =_xlfn.RANK.AVG(B6,$B6:$J6) -> 8 | M6: =_xlfn.RANK.AVG(C6,$B6:$J6) -> 4 | N6: =_xlfn.RANK.AVG(D6,$B6:$J6) -> 2 | O6: =_xlfn.RANK.AVG(E6,$B6:$J6) -> 9 | P6: =_xlfn.RANK.AVG(F6,$B6:$J6) -> 5 | Q6: =_xlfn.RANK.AVG(G6,$B6:$J6) -> 7 | R6: =_xlfn.RANK.AVG(H6,$B6:$J6) -> 1 | S6: =_xlfn.RANK.AVG(I6,$B6:$J6) -> 3 | T6: =_xlfn.RANK.AVG(J6,$B6:$J6) -> 6
A7: ERing | B7: 0.989 | C7: 0.964 | D7: 0.133 | E7: 0.844 | F7: 0.963 | G7: 0.951 | H7: 0.985 | I7: 0.874 | J7: 0.913 | L7: =_xlfn.RANK.AVG(B7,$B7:$J7) -> 1 | M7: =_xlfn.RANK.AVG(C7,$B7:$J7) -> 3 | N7: =_xlfn.RANK.AVG(D7,$B7:$J7) -> 9 | O7: =_xlfn.RANK.AVG(E7,$B7:$J7) -> 8 | P7: =_xlfn.RANK.AVG(F7,$B7:$J7) -> 4 | Q7: =_xlfn.RANK.AVG(G7,$B7:$J7) -> 5 | R7: =_xlfn.RANK.AVG(H7,$B7:$J7) -> 2 | S7: =_xlfn.RANK.AVG(I7,$B7:$J7) -> 7 | T7: =_xlfn.RANK.AVG(J7,$B7:$J7) -> 6
A8: EigenWorms | B8: 0.947 | C8: 0.593 | D8: 0.435 | E8: 0.939 | F8: 0.593 | G8: 0.557 | H8: 0.87 | I8: 0.847 | J8: 0.727 | L8: =_xlfn.RANK.AVG(B8,$B8:$J8) -> 1 | M8: =_xlfn.RANK.AVG(C8,$B8:$J8) -> 6.5 | N8: =_xlfn.RANK.AVG(D8,$B8:$J8) -> 9 | O8: =_xlfn.RANK.AVG(E8,$B8:$J8) -> 2 | P8: =_xlfn.RANK.AVG(F8,$B8:$J8) -> 6.5 | Q8: =_xlfn.RANK.AVG(G8,$B8:$J8) -> 8 | R8: =_xlfn.RANK.AVG(H8,$B8:$J8) -> 3 | S8: =_xlfn.RANK.AVG(I8,$B8:$J8) -> 4 | T8: =_xlfn.RANK.AVG(J8,$B8:$J8) -> 5
A9: Epilepsy | B9: 1 | C9: 0.989 | D9: 0.993 | E9: 0.993 | F9: 0.986 | G9: 0.985 | H9: 0.978 | I9: 0.964 | J9: 0.975 | L9: =_xlfn.RANK.AVG(B9,$B9:$J9) -> 1 | M9: =_xlfn.RANK.AVG(C9,$B9:$J9) -> 4 | N9: =_xlfn.RANK.AVG(D9,$B9:$J9) -> 2.5 | O9: =_xlfn.RANK.AVG(E9,$B9:$J9) -> 2.5 | P9: =_xlfn.RANK.AVG(F9,$B9:$J9) -> 5 | Q9: =_xlfn.RANK.AVG(G9,$B9:$J9) -> 6 | R9: =_xlfn.RANK.AVG(H9,$B9:$J9) -> 7 | S9: =_xlfn.RANK.AVG(I9,$B9:$J9) -> 9 | T9: =_xlfn.RANK.AVG(J9,$B9:$J9) -> 8
A10: EthanolConcentration | B10: 0.772 | C10: 0.309 | D10: 0.346 | E10: 0.692 | F10: 0.361 | G10: 0.623 | H10: 0.304 | I10: 0.308 | J10: 0.304 | L10: =_xlfn.RANK.AVG(B10,$B10:$J10) -> 1 | M10: =_xlfn.RANK.AVG(C10,$B10:$J10) -> 6 | N10: =_xlfn.RANK.AVG(D10,$B10:$J10) -> 5 | O10: =_xlfn.RANK.AVG(E10,$B10:$J10) -> 2 | P10: =_xlfn.RANK.AVG(F10,$B10:$J10) -> 4 | Q10: =_xlfn.RANK.AVG(G10,$B10:$J10) -> 3 | R10: =_xlfn.RANK.AVG(H10,$B10:$J10) -> 8.5 | S10: =_xlfn.RANK.AVG(I10,$B10:$J10) -> 7 | T10: =_xlfn.RANK.AVG(J10,$B10:$J10) -> 8.5
A11: FaceDetection | B11: 0.66 | C11: 0.567 | D11: 0.639 | E11: 0.61 | F11: 0.672 | G11: 0.68 | H11: 0.608 | I11: 0.501 | J11: 0.637 | L11: =_xlfn.RANK.AVG(B11,$B11:$J11) -> 3 | M11: =_xlfn.RANK.AVG(C11,$B11:$J11) -> 8 | N11: =_xlfn.RANK.AVG(D11,$B11:$J11) -> 4 | O11: =_xlfn.RANK.AVG(E11,$B11:$J11) -> 6 | P11: =_xlfn.RANK.AVG(F11,$B11:$J11) -> 2 | Q11: =_xlfn.RANK.AVG(G11,$B11:$J11) -> 1 | R11: =_xlfn.RANK.AVG(H11,$B11:$J11) -> 7 | S11: =_xlfn.RANK.AVG(I11,$B11:$J11) -> 9 | T11: =_xlfn.RANK.AVG(J11,$B11:$J11) -> 5
A12: FingerMovements | B12: 0.53 | C12: 0.604 | D12: 0.6 | E12: 0.56 | F12: 0.56 | G12: 0.614 | H12: 0.66 | I12: 0.48 | J12: 0.528 | L12: =_xlfn.RANK.AVG(B12,$B12:$J12) -> 7 | M12: =_xlfn.RANK.AVG(C12,$B12:$J12) -> 3 | N12: =_xlfn.RANK.AVG(D12,$B12:$J12) -> 4 | O12: =_xlfn.RANK.AVG(E12,$B12:$J12) -> 5.5 | P12: =_xlfn.RANK.AVG(F12,$B12:$J12) -> 5.5 | Q12: =_xlfn.RANK.AVG(G12,$B12:$J12) -> 2 | R12: =_xlfn.RANK.AVG(H12,$B12:$J12) -> 1 | S12: =_xlfn.RANK.AVG(I12,$B12:$J12) -> 9 | T12: =_xlfn.RANK.AVG(J12,$B12:$J12) -> 8
A13: HandMovementDirection | B13: 0.473 | C13: 0.324 | D13: 0.446 | E13: 0.351 | F13: 0.405 | G13: 0.662 | H13: 0.432 | I13: 0.338 | J13: 0.322 | L13: =_xlfn.RANK.AVG(B13,$B13:$J13) -> 2 | M13: =_xlfn.RANK.AVG(C13,$B13:$J13) -> 8 | N13: =_xlfn.RANK.AVG(D13,$B13:$J13) -> 3 | O13: =_xlfn.RANK.AVG(E13,$B13:$J13) -> 6 | P13: =_xlfn.RANK.AVG(F13,$B13:$J13) -> 5 | Q13: =_xlfn.RANK.AVG(G13,$B13:$J13) -> 1 | R13: =_xlfn.RANK.AVG(H13,$B13:$J13) -> 4 | S13: =_xlfn.RANK.AVG(I13,$B13:$J13) -> 7 | T13: =_xlfn.RANK.AVG(J13,$B13:$J13) -> 9
... A27: UWaveGestureLibrary | B27: 0.928 | C27: 0.924 | D27: 0.894 | E27: 0.847 | F27: 0.891 | G27: 0.903 | H27: 0.919 | I27: 0.906 | J27: 0.873 | L27: =_xlfn.RANK.AVG(B27,$B27:$J27) -> 1 | M27: =_xlfn.RANK.AVG(C27,$B27:$J27) -> 2 | N27: =_xlfn.RANK.AVG(D27,$B27:$J27) -> 6 | O27: =_xlfn.RANK.AVG(E27,$B27:$J27) -> 9 | P27: =_xlfn.RANK.AVG(F27,$B27:$J27) -> 7 | Q27: =_xlfn.RANK.AVG(G27,$B27:$J27) -> 5 | R27: =_xlfn.RANK.AVG(H27,$B27:$J27) -> 3 | S27: =_xlfn.RANK.AVG(I27,$B27:$J27) -> 4 | T27: =_xlfn.RANK.AVG(J27,$B27:$J27) -> 8
A28: Average | B28: =ROUND(AVERAGE(B1:B27),3) -> 0.748 | C28: =ROUND(AVERAGE(C1:C27),3) -> 0.699 | D28: =ROUND(AVERAGE(D1:D27),3) -> 0.673 | E28: =ROUND(AVERAGE(E1:E27),3) -> 0.682 | F28: =ROUND(AVERAGE(F1:F27),3) -> 0.71 | G28: =ROUND(AVERAGE(G1:G27),3) -> 0.749 | H28: =ROUND(AVERAGE(H1:H27),3) -> 0.736 | I28: =ROUND(AVERAGE(I1:I27),3) -> 0.68 | J28: =ROUND(AVERAGE(J1:J27),3) -> 0.691 | L28: =AVERAGE(L1:L27) -> 3.9038462 | M28: =AVERAGE(M1:M27) -> 5 | N28: =AVERAGE(N1:N27) -> 5.1153846 | O28: =AVERAGE(O1:O27) -> 6.3461538 | P28: =AVERAGE(P1:P27) -> 4.4423077 | Q28: =AVERAGE(Q1:Q27) -> 3.4807692 | R28: =AVERAGE(R1:R27) -> 3.9230769 | S28: =AVERAGE(S1:S27) -> 6.7692308 | T28: =AVERAGE(T1:T27) -> 6.0192308
A29: Mean Rank | B29: =ROUND(L28,3) -> 3.904 | C29: =ROUND(M28,3) -> 5 | D29: =ROUND(N28,3) -> 5.115 | E29: =ROUND(O28,3) -> 6.346 | F29: =ROUND(P28,3) -> 4.442 | G29: =ROUND(Q28,3) -> 3.481 | H29: =ROUND(R28,3) -> 3.923 | I29: =ROUND(S28,3) -> 6.769 | J29: =ROUND(T28,3) -> 6.019
